<?xml version="1.0"?>

<robot name="thesis_robot" xmlns:xacro="http://ros.org/wiki/xacro">

  <!-- <xacro:include filename="$(find thesis_robot)/urdf/thesis_robot.gazebo.xacro"/> -->
  <!-- <xacro:include filename="$(find thesis_robot)/urdf/materials.xacro" /> -->

<!-- Notes: Hiennd, 27/07/2020
      ref: http://wiki.ros.org/urdf/XML/link
      ref: http://wiki.ros.org/urdf/Tutorials/Adding%20Physical%20and%20Collision%20Properties%20to%20a%20URDF%20Model
      ref: http://wiki.ros.org/urdf/XML/joint

      ###
      1.570796   == pi/2  == Quay 1 góc 90 độ; pi = 3.14159
      ##
      - Các khớp (join) có kiểu: type="continuous" cần được pub lên (sensor_msgs::JointState)
      - Các joint (khớp) kiểu continue sẽ có thêm 01 thông số quan tâm: Joint Axis
      - <axis> (optional: defaults to (1,0,0)) = xyz
      Đây là trục quay cho khớp quay vòng tròn, trục dịch cho khớp hình lăng trụ và bề mặt bình thường cho khớp phẳng.
      Trục được chỉ định trong khung tham chiếu chung. Các khớp cố định (fix) và nổi (floating) không sử dụng trường trục.
      ##
      Những phần dưới này, chỉ liên quan đến Gazebo:
      	<collision>	== Phạm vi va chạm == kích thước của khối
        ....
        </collision>
        ##########
        <inertial>	== Liên quan đến quán tính chuyển đông trong Gazebo
          //Ma trận quán tính quay 3x3: ixx, ixy ....
          mu - Hệ số ma sát
          kp - Hệ số độ cứng
          kd - Hệ số giảm chấn
          //
          <mass value="10"/> 	== Khối lượng của liên kết (kg)
          <inertia ixx="0.4" ixy="0.0" ixz="0.0" iyy="0.4" iyz="0.0" izz="0.2"/>
        </inertial>
        #########

 -->
  <!-- link gốc sẽ ko có joint  -->
  <link name="base_footprint"/>
  
  <joint name="base_joint" type="fixed">
    <parent link="base_footprint"/>
    <child link="base_link"/>
    <origin xyz="0.0 0.0 0.0" rpy="0 0 0"/>
  </joint>

<!-- Base Link -->
<!-- Vì ko đặt riêng link = "base_footprint" nên mọi mô tả (geometry) đều được tính từ tâm [0,0,0] theo cả 3 chiều nên khi tính độ cao phải chia /2 -->
  <link name="base_link">
    <visual>
      <origin xyz="0 0 0.0365" rpy="0 0 0" />
      <geometry>
          <box size="0.3757 0.280 0.003"/> <!-- Tấm Nhôm AL = 3mm -->
      </geometry>
      <material name="blue">
        <color rgba="0 0.5 1 1"/>
      </material>
    </visual>
    <!-- Khu vực va chạm = Cả khối robot, Chiều cao toàn bộ = 33cm-->
    <collision>
       <origin xyz="0 0 0.165" rpy="0 0 0" /> <!-- 0.165 = 0.33/2-->
      <geometry>
        <box size="0.3757 0.280 0.33"/>
      </geometry>
    </collision>

    <!-- Thử nghiệm quán tính cho Gazebo : Khoi luong ( = 5.62 kg)-->

    <!-- Caster -->
    <!-- Bánh xe caster đường kính bằng 2 bánh xe kia, rộng 4cm, xyz = 9.5cm, 0, 6.25cm-->
    <visual name="caster">
      <origin xyz="0.095 0 0.0625" rpy="1.570796 0 0" />
      <geometry>
          <cylinder length="0.04" radius="0.0625" />
      </geometry>
      <material name="black">
        <color rgba="0.05 0.05 0.05 1"/>
      </material>
    </visual>

    <!-- Tam phia tren de MCU + Linux -->
    <visual name="base_level1">
      <origin xyz="0 0 0.125" rpy="0 0 0" />
      <geometry>
          <box size="0.3757 0.280 0.003"/> <!-- Tấm Nhôm AL = 3mm -->
      </geometry>
      <material name="blue">
        <color rgba="0 0.5 1 1"/>
      </material>
    </visual>

     <!-- Tam phia tren cung -->
    <visual name="base_level2">
      <origin xyz="0 0 0.325" rpy="0 0 0" /> <!--125+200=325cm-->
      <geometry>
          <box size="0.3757 0.280 0.003"/> <!-- Tấm Nhôm AL = 3mm -->
      </geometry>
      <material name="blue">
        <color rgba="0 0.5 1 1"/>
      </material>
    </visual>

     <!-- 4 cot khung robot -->
    <visual name="row1">
      <origin xyz="0.125 0.125 0.180" rpy="0 0 0" />
      <geometry>
          <box size="0.02 0.02 0.3"/>
      </geometry>
      <material name="yellow">
        <color rgba="1 1 0.75 1"/>
      </material>
    </visual>

    <visual name="row2">
      <origin xyz="-0.150 -0.125 0.180" rpy="0 0 0" />
      <geometry>
          <box size="0.02 0.02 0.3"/>
      </geometry>
      <material name="yellow">
        <color rgba="1 1 0.75 1"/>
      </material>
    </visual>

    <visual name="row3">
      <origin xyz="-0.150 0.125 0.180" rpy="0 0 0" />
      <geometry>
          <box size="0.02 0.02 0.3"/>
      </geometry>
      <material name="yellow">
        <color rgba="1 1 0.75 1"/>
      </material>
      </visual>

    <visual name="row4">
      <origin xyz="0.125 -0.125 0.180" rpy="0 0 0" />
      <geometry>
          <box size="0.02 0.02 0.3"/>
      </geometry>
      <material name="yellow">
        <color rgba="1 1 0.75 1"/>
      </material>
    </visual>

    <!-- De phia duoi Lidar -->
    <visual name="DeLidar">
      <origin xyz="0 0 0.140" rpy="0 0 0" /> <!--12+5/2-->
      <geometry>
          <box size="0.11 0.07 0.025"/>
      </geometry>
      <material name="yellow">
        <color rgba="1 1 0.75 1"/>
      </material>
    </visual>
  </link>

  <!-- Left Wheel: wheel_left_joint && wheel_left_link -->
  <link name="wheel_left_link">
    <visual>
      <origin xyz="0 0 0" rpy="1.570796 0 0" />
      <geometry>
          <cylinder length="0.04" radius="0.0625" />
      </geometry>
      <material name="black"/>
    </visual>

    <collision>
      <origin xyz="0 0 0" rpy="1.570796 0 0" />
      <geometry>
        <cylinder length="0.04" radius="0.0625" />
      </geometry>
    </collision>

    <inertial>
			<mass value="0.1"/>
			<origin xyz="0 0 0"/>
			<inertia ixx="0.012411765597" ixy="-0.000711733678" ixz="0.00050272983"
				 iyy="0.015218160428" iyz="-0.000004273467" izz="0.011763977943"/>
  	</inertial>
  </link>

  <!-- Các khớp (join) có kiểu: type="continuous" cần được pub lên (sensor_msgs::JointState) -->
  <joint name="wheel_left_joint" type="continuous">
    <parent link="base_link"/>
    <child link="wheel_left_link"/>
    <origin xyz="-0.12535 0.165 0.0625" rpy="0 0 0" /> <!--0.16+0.005-->
    <axis xyz="0 1 0" />
  </joint>

    <!-- Right Wheel : wheel_right_joint && wheel_right_link-->
  <link name="wheel_right_link">
    <visual>
      <origin xyz="0 0 0" rpy="1.570796 0 0" />
      <geometry>
          <cylinder length="0.04" radius="0.0625" />
      </geometry>
      <material name="black">
        <color rgba="0.05 0.05 0.05 1"/>
      </material>
    </visual>

    <collision>
      <origin xyz="0 0 0" rpy="1.570796 0 0" />
      <geometry>
        <cylinder length="0.04" radius="0.0625" />
      </geometry>
    </collision>

    <inertial>
			<mass value="0.1"/>
			<origin xyz="0 0 0"/>
			<inertia ixx="0.012411765597" ixy="-0.000711733678" ixz="0.00050272983"
				 iyy="0.015218160428" iyz="-0.000004273467" izz="0.011763977943"/>
  	</inertial>

  </link>

  <!-- Các khớp (join) có kiểu: type="continuous" cần được pub lên (sensor_msgs::JointState) -->
  <joint name="wheel_right_joint" type="continuous">
    <parent link="base_link"/>
    <child link="wheel_right_link"/>
    <origin xyz="-0.12535 -0.165 0.0625" rpy="0 0 0" />
    <axis xyz="0 1 0" />
  </joint>

  <!-- IMU -->
  <joint name="imu_joint" type="fixed">
    <parent link="base_link"/>
    <child link="imu_link"/>
    <!-- cho imu == odom -->
    <origin xyz="0 0 0.0365" rpy="0 0 0" />
  </joint>

  <link name="imu_link"/>

  <!-- Lidar : Đang để nhầm chiều, xoay 180 độ => rpy="0 0 3.14159" -->
  <joint name="scan_joint" type="fixed">
    <parent link="base_link"/>
    <child link="base_scan"/>
    <origin xyz="0 0 0.175" rpy="0 0 3.14159"/>  <!-- Lidar at center, high = 17.5cm; chiều đặt đang nhầm 180 độ -->
  </joint>

  <link name="base_scan">
    <visual>
      <origin xyz="0 0 0.0" rpy="0 0 3.14159"/>   <!-- Quay khối vật lý 180 độ # joint -->
      <geometry>
        <mesh filename="package://thesis_robot/meshes/lds.stl" scale="0.001 0.001 0.001"/>
      </geometry>
      <material name="dark"/>
    </visual>

    <collision>
      <origin xyz="0 0 0" rpy="0 0 0"/>
      <geometry>
        <cylinder length="0.0315" radius="0.055"/> <!--Chỉ cần đưa ra kích thước, chiều cao khối chạy theo chiều cao của joint-->
      </geometry>
    </collision>

    <inertial>
      <mass value="0.114" />
      <origin xyz="0 0 0" />
      <inertia ixx="0.001" ixy="0.0" ixz="0.0"
               iyy="0.001" iyz="0.0"
               izz="0.001" />
    </inertial>
  </link>

</robot>
